{
 "cells": [
  {
   "cell_type": "code",
   "execution_count": 1,
   "metadata": {},
   "outputs": [
    {
     "name": "stdout",
     "output_type": "stream",
     "text": [
      "TASK: \"\"\"\n",
      "creat a sum of a and b\n",
      "\"\"\"\n",
      "REUSE: False\n",
      "ARGS: [a, b]\n",
      "- a: \"\"\"\n",
      "object of type builtins.list\n",
      "\"\"\"\n",
      "- b: \"\"\"\n",
      "object of type builtins.dict\n",
      "\"\"\"\n"
     ]
    }
   ],
   "source": [
    "from aiknows import gpt\n",
    "from aiknows.runtime import finish_task_ok, finish_task_error\n",
    "\n",
    "from aiknows.runtime import setup_task\n",
    "a, b = [], {}\n",
    "setup_task(\n",
    "    task='creat a sum of a and b',\n",
    "    reuse=False,\n",
    "    args={'a': a, 'b': b},\n",
    "    globals=globals(),\n",
    ")\n",
    "del setup_task"
   ]
  },
  {
   "cell_type": "code",
   "execution_count": 2,
   "metadata": {},
   "outputs": [],
   "source": [
    "# this task setup just doesn't make sense\n",
    "finish_task_error('unable to create a sum of a list and a dict');"
   ]
  },
  {
   "cell_type": "code",
   "execution_count": 3,
   "metadata": {},
   "outputs": [
    {
     "name": "stdout",
     "output_type": "stream",
     "text": [
      "TASK: \"\"\"\n",
      "read file notexists.txt\n",
      "\"\"\"\n",
      "REUSE: False\n",
      "ARGS: []\n"
     ]
    }
   ],
   "source": [
    "from aiknows.runtime import setup_task\n",
    "setup_task(\n",
    "    task='read file notexists.txt',\n",
    "    reuse=False,\n",
    "    args=None,\n",
    "    globals=globals(),\n",
    ")\n",
    "del setup_task"
   ]
  },
  {
   "cell_type": "code",
   "execution_count": 4,
   "metadata": {},
   "outputs": [
    {
     "ename": "FileNotFoundError",
     "evalue": "[Errno 2] No such file or directory: 'notexists.txt'",
     "output_type": "error",
     "traceback": [
      "\u001b[0;31m---------------------------------------------------------------------------\u001b[0m",
      "\u001b[0;31mFileNotFoundError\u001b[0m                         Traceback (most recent call last)",
      "Cell \u001b[0;32mIn[4], line 1\u001b[0m\n\u001b[0;32m----> 1\u001b[0m \u001b[38;5;28;01mwith\u001b[39;00m \u001b[38;5;28;43mopen\u001b[39;49m\u001b[43m(\u001b[49m\u001b[38;5;124;43m'\u001b[39;49m\u001b[38;5;124;43mnotexists.txt\u001b[39;49m\u001b[38;5;124;43m'\u001b[39;49m\u001b[43m,\u001b[49m\u001b[43m \u001b[49m\u001b[38;5;124;43m'\u001b[39;49m\u001b[38;5;124;43mr\u001b[39;49m\u001b[38;5;124;43m'\u001b[39;49m\u001b[43m)\u001b[49m \u001b[38;5;28;01mas\u001b[39;00m f:\n\u001b[1;32m      2\u001b[0m     content \u001b[38;5;241m=\u001b[39m f\u001b[38;5;241m.\u001b[39mread()\n\u001b[1;32m      4\u001b[0m finish_task_ok(content);\n",
      "File \u001b[0;32m~/.miniconda3/envs/aiknows/lib/python3.8/site-packages/IPython/core/interactiveshell.py:284\u001b[0m, in \u001b[0;36m_modified_open\u001b[0;34m(file, *args, **kwargs)\u001b[0m\n\u001b[1;32m    277\u001b[0m \u001b[38;5;28;01mif\u001b[39;00m file \u001b[38;5;129;01min\u001b[39;00m {\u001b[38;5;241m0\u001b[39m, \u001b[38;5;241m1\u001b[39m, \u001b[38;5;241m2\u001b[39m}:\n\u001b[1;32m    278\u001b[0m     \u001b[38;5;28;01mraise\u001b[39;00m \u001b[38;5;167;01mValueError\u001b[39;00m(\n\u001b[1;32m    279\u001b[0m         \u001b[38;5;124mf\u001b[39m\u001b[38;5;124m\"\u001b[39m\u001b[38;5;124mIPython won\u001b[39m\u001b[38;5;124m'\u001b[39m\u001b[38;5;124mt let you open fd=\u001b[39m\u001b[38;5;132;01m{\u001b[39;00mfile\u001b[38;5;132;01m}\u001b[39;00m\u001b[38;5;124m by default \u001b[39m\u001b[38;5;124m\"\u001b[39m\n\u001b[1;32m    280\u001b[0m         \u001b[38;5;124m\"\u001b[39m\u001b[38;5;124mas it is likely to crash IPython. If you know what you are doing, \u001b[39m\u001b[38;5;124m\"\u001b[39m\n\u001b[1;32m    281\u001b[0m         \u001b[38;5;124m\"\u001b[39m\u001b[38;5;124myou can use builtins\u001b[39m\u001b[38;5;124m'\u001b[39m\u001b[38;5;124m open.\u001b[39m\u001b[38;5;124m\"\u001b[39m\n\u001b[1;32m    282\u001b[0m     )\n\u001b[0;32m--> 284\u001b[0m \u001b[38;5;28;01mreturn\u001b[39;00m \u001b[43mio_open\u001b[49m\u001b[43m(\u001b[49m\u001b[43mfile\u001b[49m\u001b[43m,\u001b[49m\u001b[43m \u001b[49m\u001b[38;5;241;43m*\u001b[39;49m\u001b[43margs\u001b[49m\u001b[43m,\u001b[49m\u001b[43m \u001b[49m\u001b[38;5;241;43m*\u001b[39;49m\u001b[38;5;241;43m*\u001b[39;49m\u001b[43mkwargs\u001b[49m\u001b[43m)\u001b[49m\n",
      "\u001b[0;31mFileNotFoundError\u001b[0m: [Errno 2] No such file or directory: 'notexists.txt'"
     ]
    }
   ],
   "source": [
    "with open('notexists.txt', 'r') as f:\n",
    "    content = f.read()\n",
    "\n",
    "finish_task_ok(content);"
   ]
  },
  {
   "cell_type": "code",
   "execution_count": 5,
   "metadata": {},
   "outputs": [],
   "source": [
    "# last exception is direct cause or innability to complete task, so we mark it with flag\n",
    "finish_task_error('file from task description isn\\'t exists', error_cause=True);"
   ]
  }
 ],
 "metadata": {
  "kernelspec": {
   "display_name": "aiknows",
   "language": "python",
   "name": "python3"
  },
  "language_info": {
   "name": "python",
   "version": "3.8.16"
  }
 },
 "nbformat": 4,
 "nbformat_minor": 2
}
